
#######################################################################
# +-----------------------------------------------------------------+ #
# |                            BO3 object                           | #
# +-----------------------------------------------------------------+ #
#######################################################################

Author: Unknown

Description: No description given

Version: 3

SettingsMode: WriteWithoutComments


#######################################################################
# +-----------------------------------------------------------------+ #
# |                          Main settings                          | #
# +-----------------------------------------------------------------+ #
#######################################################################

Tree: true

Frequency: 0

Rarity: 100.0

MaxSpawn: 0

RotateRandomly: false

SpawnHeight: highestBlock

SpawnHeightOffset: 0

SpawnHeightVariance: 0

##############################
# Height Limits for the BO3. #
##############################

MinHeight: 0

MaxHeight: 256

######################
# Extrusion settings #
######################

ExtrudeMode: None

ExtrudeThroughBlocks: minecraft:air

MaxBranchDepth: 10


#######################################################################
# +-----------------------------------------------------------------+ #
# |                      Source block settings                      | #
# +-----------------------------------------------------------------+ #
#######################################################################

SourceBlocks: minecraft:air

MaxPercentageOutsideSourceBlock: 100

OutsideSourceBlock: placeAnyway

DoReplaceBlocks: true

IsOTGPlus: false


#######################################################################
# +-----------------------------------------------------------------+ #
# |                              Blocks                             | #
# +-----------------------------------------------------------------+ #
#######################################################################

B(-5,9,-3,minecraft:spruce_leaves)
B(-5,19,-3,minecraft:spruce_leaves)
B(-5,5,-2,minecraft:spruce_leaves)
B(-5,12,-2,minecraft:spruce_leaves)
B(-5,5,-1,minecraft:spruce_leaves)
B(-5,10,-1,minecraft:spruce_leaves)
B(-5,16,-1,minecraft:spruce_leaves)
B(-5,15,0,minecraft:spruce_leaves[distance=2,persistent=false])
B(-5,20,0,minecraft:spruce_leaves)
B(-5,5,1,minecraft:spruce_leaves)
B(-5,8,1,minecraft:spruce_leaves)
B(-5,15,1,minecraft:spruce_leaves)
B(-5,8,2,minecraft:spruce_leaves)
B(-5,17,2,minecraft:spruce_leaves)
B(-5,17,3,minecraft:spruce_leaves[distance=2,persistent=false])
B(-4,9,-4,minecraft:spruce_leaves)
B(-4,14,-4,minecraft:spruce_leaves)
B(-4,19,-4,minecraft:spruce_leaves)
B(-4,5,-3,minecraft:spruce_leaves)
B(-4,9,-3,minecraft:spruce_log)
B(-4,10,-3,minecraft:spruce_leaves)
B(-4,12,-3,minecraft:spruce_leaves)
B(-4,19,-3,minecraft:spruce_log)
B(-4,20,-3,minecraft:spruce_leaves)
B(-4,5,-2,minecraft:spruce_log)
B(-4,6,-2,minecraft:spruce_leaves)
B(-4,9,-2,minecraft:spruce_leaves)
B(-4,10,-2,minecraft:spruce_leaves)
B(-4,12,-2,minecraft:spruce_log)
B(-4,13,-2,minecraft:spruce_leaves)
B(-4,16,-2,minecraft:spruce_leaves)
B(-4,19,-2,minecraft:spruce_leaves)
B(-4,23,-2,minecraft:spruce_leaves[distance=2,persistent=false])
B(-4,5,-1,minecraft:spruce_log)
B(-4,6,-1,minecraft:spruce_leaves)
B(-4,10,-1,minecraft:spruce_log)
B(-4,11,-1,minecraft:spruce_leaves)
B(-4,12,-1,minecraft:spruce_leaves)
B(-4,16,-1,minecraft:spruce_log)
B(-4,17,-1,minecraft:spruce_leaves)
B(-4,20,-1,minecraft:spruce_leaves)
B(-4,23,-1,minecraft:spruce_leaves)
B(-4,5,0,minecraft:spruce_leaves)
B(-4,6,0,minecraft:spruce_leaves)
B(-4,8,0,minecraft:spruce_leaves)
B(-4,9,0,minecraft:spruce_leaves[distance=2,persistent=false])
B(-4,10,0,minecraft:spruce_leaves)
B(-4,15,0,minecraft:spruce_leaves)
B(-4,16,0,minecraft:spruce_leaves)
B(-4,20,0,minecraft:spruce_log)
B(-4,21,0,minecraft:spruce_leaves)
B(-4,5,1,minecraft:spruce_log)
B(-4,6,1,minecraft:spruce_leaves)
B(-4,8,1,minecraft:spruce_log)
B(-4,9,1,minecraft:spruce_leaves)
B(-4,13,1,minecraft:spruce_leaves)
B(-4,15,1,minecraft:spruce_log)
B(-4,16,1,minecraft:spruce_leaves)
B(-4,17,1,minecraft:spruce_leaves)
B(-4,20,1,minecraft:spruce_leaves)
B(-4,5,2,minecraft:spruce_leaves)
B(-4,8,2,minecraft:spruce_log)
B(-4,9,2,minecraft:spruce_leaves)
B(-4,12,2,minecraft:spruce_leaves)
B(-4,15,2,minecraft:spruce_leaves)
B(-4,17,2,minecraft:spruce_log)
B(-4,18,2,minecraft:spruce_leaves)
B(-4,8,3,minecraft:spruce_leaves)
B(-4,15,3,minecraft:spruce_leaves[distance=2,persistent=false])
B(-4,17,3,minecraft:spruce_leaves)
B(-3,14,-5,minecraft:spruce_leaves)
B(-3,5,-4,minecraft:spruce_leaves)
B(-3,9,-4,minecraft:spruce_leaves)
B(-3,14,-4,minecraft:spruce_log)
B(-3,15,-4,minecraft:spruce_leaves)
B(-3,17,-4,minecraft:spruce_leaves)
B(-3,19,-4,minecraft:spruce_leaves)
B(-3,9,-3,minecraft:spruce_log)
B(-3,10,-3,minecraft:spruce_leaves)
B(-3,14,-3,minecraft:spruce_leaves)
B(-3,15,-3,minecraft:spruce_leaves)
B(-3,17,-3,minecraft:spruce_leaves)
B(-3,19,-3,minecraft:spruce_leaves)
B(-3,5,-2,minecraft:spruce_leaves)
B(-3,6,-2,minecraft:spruce_leaves)
B(-3,9,-2,minecraft:spruce_log)
B(-3,10,-2,minecraft:spruce_leaves)
B(-3,12,-2,minecraft:spruce_leaves)
B(-3,15,-2,minecraft:spruce_leaves)
B(-3,17,-2,minecraft:spruce_leaves)
B(-3,19,-2,minecraft:spruce_log)
B(-3,20,-2,minecraft:spruce_leaves)
B(-3,21,-2,minecraft:spruce_leaves)
B(-3,23,-2,minecraft:spruce_leaves)
B(-3,26,-2,minecraft:spruce_leaves[distance=2,persistent=false])
B(-3,6,-1,minecraft:spruce_log)
B(-3,7,-1,minecraft:spruce_leaves)
B(-3,9,-1,minecraft:spruce_leaves)
B(-3,10,-1,minecraft:spruce_log)
B(-3,11,-1,minecraft:spruce_leaves)
B(-3,12,-1,minecraft:spruce_log)
B(-3,13,-1,minecraft:spruce_leaves)
B(-3,15,-1,minecraft:spruce_leaves)
B(-3,17,-1,minecraft:spruce_log)
B(-3,18,-1,minecraft:spruce_leaves)
B(-3,19,-1,minecraft:spruce_leaves)
B(-3,20,-1,minecraft:spruce_leaves)
B(-3,23,-1,minecraft:spruce_log)
B(-3,24,-1,minecraft:spruce_leaves)
B(-3,25,-1,minecraft:spruce_leaves)
B(-3,26,-1,minecraft:spruce_leaves)
B(-3,27,-1,minecraft:spruce_leaves)
B(-3,28,-1,minecraft:spruce_leaves)
B(-3,29,-1,minecraft:spruce_leaves[distance=2,persistent=false])
B(-3,6,0,minecraft:spruce_log)
B(-3,7,0,minecraft:spruce_leaves)
B(-3,9,0,minecraft:spruce_leaves)
B(-3,10,0,minecraft:spruce_leaves)
B(-3,12,0,minecraft:spruce_leaves)
B(-3,13,0,minecraft:spruce_leaves)
B(-3,15,0,minecraft:spruce_log)
B(-3,16,0,minecraft:spruce_leaves)
B(-3,17,0,minecraft:spruce_leaves)
B(-3,20,0,minecraft:spruce_log)
B(-3,21,0,minecraft:spruce_leaves)
B(-3,23,0,minecraft:spruce_leaves)
B(-3,5,1,minecraft:spruce_log)
B(-3,6,1,minecraft:spruce_leaves)
B(-3,8,1,minecraft:spruce_leaves)
B(-3,9,1,minecraft:spruce_log)
B(-3,10,1,minecraft:spruce_leaves)
B(-3,13,1,minecraft:spruce_log)
B(-3,14,1,minecraft:spruce_leaves)
B(-3,15,1,minecraft:spruce_leaves)
B(-3,16,1,minecraft:spruce_leaves[distance=2,persistent=false])
B(-3,17,1,minecraft:spruce_leaves)
B(-3,20,1,minecraft:spruce_leaves)
B(-3,22,1,minecraft:spruce_leaves)
B(-3,5,2,minecraft:spruce_leaves)
B(-3,7,2,minecraft:spruce_leaves[distance=2,persistent=false])
B(-3,8,2,minecraft:spruce_leaves)
B(-3,9,2,minecraft:spruce_leaves)
B(-3,12,2,minecraft:spruce_log)
B(-3,13,2,minecraft:spruce_leaves)
B(-3,15,2,minecraft:spruce_leaves[distance=2,persistent=false])
B(-3,17,2,minecraft:spruce_log)
B(-3,18,2,minecraft:spruce_leaves)
B(-3,7,3,minecraft:spruce_leaves)
B(-3,12,3,minecraft:spruce_leaves)
B(-3,13,3,minecraft:spruce_leaves)
B(-3,17,3,minecraft:spruce_log)
B(-3,18,3,minecraft:spruce_leaves)
B(-3,5,4,minecraft:spruce_leaves)
B(-3,13,4,minecraft:spruce_leaves[distance=2,persistent=false])
B(-3,17,4,minecraft:spruce_leaves)
B(-2,5,-5,minecraft:spruce_leaves)
B(-2,8,-5,minecraft:spruce_leaves)
B(-2,14,-5,minecraft:spruce_leaves)
B(-2,17,-5,minecraft:spruce_leaves)
B(-2,19,-5,minecraft:spruce_leaves)
B(-2,5,-4,minecraft:spruce_log)
B(-2,6,-4,minecraft:spruce_leaves)
B(-2,8,-4,minecraft:spruce_leaves)
B(-2,13,-4,minecraft:spruce_leaves)
B(-2,14,-4,minecraft:spruce_log)
B(-2,15,-4,minecraft:spruce_leaves)
B(-2,17,-4,minecraft:spruce_log)
B(-2,18,-4,minecraft:spruce_leaves)
B(-2,19,-4,minecraft:spruce_log)
B(-2,20,-4,minecraft:spruce_leaves)
B(-2,5,-3,minecraft:spruce_leaves)
B(-2,6,-3,minecraft:spruce_leaves)
B(-2,8,-3,minecraft:spruce_leaves)
B(-2,9,-3,minecraft:spruce_leaves)
B(-2,10,-3,minecraft:spruce_leaves[distance=2,persistent=false])
B(-2,14,-3,minecraft:spruce_leaves)
B(-2,15,-3,minecraft:spruce_log)
B(-2,16,-3,minecraft:spruce_leaves)
B(-2,17,-3,minecraft:spruce_log)
B(-2,18,-3,minecraft:spruce_leaves)
B(-2,19,-3,minecraft:spruce_log)
B(-2,20,-3,minecraft:spruce_leaves)
B(-2,21,-3,minecraft:spruce_leaves)
B(-2,23,-3,minecraft:spruce_leaves[distance=2,persistent=false])
B(-2,26,-3,minecraft:spruce_leaves[distance=2,persistent=false])
B(-2,9,-2,minecraft:spruce_log)
B(-2,10,-2,minecraft:spruce_leaves)
B(-2,11,-2,minecraft:spruce_leaves[distance=2,persistent=false])
B(-2,12,-2,minecraft:spruce_leaves[distance=2,persistent=false])
B(-2,13,-2,minecraft:spruce_leaves)
B(-2,14,-2,minecraft:spruce_leaves)
B(-2,15,-2,minecraft:spruce_log)
B(-2,17,-2,minecraft:spruce_leaves)
B(-2,19,-2,minecraft:spruce_log)
B(-2,20,-2,minecraft:spruce_leaves)
B(-2,21,-2,minecraft:spruce_log)
B(-2,22,-2,minecraft:spruce_leaves)
B(-2,23,-2,minecraft:spruce_leaves)
B(-2,24,-2,minecraft:spruce_leaves)
B(-2,25,-2,minecraft:spruce_leaves)
B(-2,26,-2,minecraft:spruce_leaves)
B(-2,27,-2,minecraft:spruce_leaves)
B(-2,28,-2,minecraft:spruce_leaves)
B(-2,6,-1,minecraft:spruce_leaves)
B(-2,9,-1,minecraft:spruce_leaves)
B(-2,10,-1,minecraft:spruce_log)
B(-2,11,-1,minecraft:spruce_leaves)
B(-2,12,-1,minecraft:spruce_leaves)
B(-2,13,-1,minecraft:spruce_log)
B(-2,14,-1,minecraft:spruce_leaves)
B(-2,15,-1,minecraft:spruce_leaves)
B(-2,17,-1,minecraft:spruce_log)
B(-2,18,-1,minecraft:spruce_leaves)
B(-2,19,-1,minecraft:spruce_log)
B(-2,20,-1,minecraft:spruce_log)
B(-2,21,-1,minecraft:spruce_leaves)
B(-2,23,-1,minecraft:spruce_log)
B(-2,24,-1,minecraft:spruce_leaves)
B(-2,25,-1,minecraft:spruce_log)
B(-2,26,-1,minecraft:spruce_log)
B(-2,27,-1,minecraft:spruce_log)
B(-2,28,-1,minecraft:spruce_log)
B(-2,29,-1,minecraft:spruce_leaves)
B(-2,30,-1,minecraft:spruce_leaves[distance=2,persistent=false])
B(-2,6,0,minecraft:spruce_log)
B(-2,7,0,minecraft:spruce_leaves)
B(-2,9,0,minecraft:spruce_log)
B(-2,10,0,minecraft:spruce_leaves)
B(-2,11,0,minecraft:spruce_leaves)
B(-2,12,0,minecraft:spruce_leaves)
B(-2,13,0,minecraft:spruce_log)
B(-2,14,0,minecraft:spruce_leaves)
B(-2,15,0,minecraft:spruce_log)
B(-2,16,0,minecraft:spruce_leaves)
B(-2,17,0,minecraft:spruce_leaves)
B(-2,18,0,minecraft:spruce_leaves)
B(-2,20,0,minecraft:spruce_leaves)
B(-2,22,0,minecraft:spruce_leaves)
B(-2,23,0,minecraft:spruce_leaves)
B(-2,24,0,minecraft:spruce_leaves)
B(-2,25,0,minecraft:spruce_leaves)
B(-2,26,0,minecraft:spruce_leaves)
B(-2,28,0,minecraft:spruce_leaves)
B(-2,6,1,minecraft:spruce_log)
B(-2,7,1,minecraft:spruce_leaves)
B(-2,9,1,minecraft:spruce_log)
B(-2,10,1,minecraft:spruce_leaves)
B(-2,13,1,minecraft:spruce_log)
B(-2,14,1,minecraft:spruce_leaves)
B(-2,15,1,minecraft:spruce_leaves)
B(-2,16,1,minecraft:spruce_leaves)
B(-2,17,1,minecraft:spruce_log)
B(-2,18,1,minecraft:spruce_leaves)
B(-2,19,1,minecraft:spruce_leaves[distance=2,persistent=false])
B(-2,22,1,minecraft:spruce_log)
B(-2,23,1,minecraft:spruce_leaves)
B(-2,6,2,minecraft:spruce_leaves)
B(-2,7,2,minecraft:spruce_leaves)
B(-2,8,2,minecraft:spruce_leaves[distance=2,persistent=false])
B(-2,9,2,minecraft:spruce_leaves)
B(-2,13,2,minecraft:spruce_leaves)
B(-2,17,2,minecraft:spruce_leaves)
B(-2,18,2,minecraft:spruce_leaves)
B(-2,19,2,minecraft:spruce_leaves[distance=2,persistent=false])
B(-2,22,2,minecraft:spruce_leaves)
B(-2,5,3,minecraft:spruce_leaves)
B(-2,7,3,minecraft:spruce_log)
B(-2,8,3,minecraft:spruce_leaves)
B(-2,13,3,minecraft:spruce_log)
B(-2,14,3,minecraft:spruce_leaves)
B(-2,17,3,minecraft:spruce_leaves)
B(-2,18,3,minecraft:spruce_leaves)
B(-2,5,4,minecraft:spruce_log)
B(-2,6,4,minecraft:spruce_leaves)
B(-2,7,4,minecraft:spruce_leaves)
B(-2,13,4,minecraft:spruce_leaves)
B(-2,5,5,minecraft:spruce_leaves)
B(-2,13,5,minecraft:spruce_leaves[distance=2,persistent=false])
B(-1,8,-6,minecraft:spruce_leaves)
B(-1,6,-5,minecraft:spruce_leaves)
B(-1,8,-5,minecraft:spruce_log)
B(-1,9,-5,minecraft:spruce_leaves)
B(-1,11,-5,minecraft:spruce_leaves)
B(-1,17,-5,minecraft:spruce_leaves[distance=2,persistent=false])
B(-1,6,-4,minecraft:spruce_leaves)
B(-1,8,-4,minecraft:spruce_log)
B(-1,9,-4,minecraft:spruce_leaves)
B(-1,11,-4,minecraft:spruce_leaves)
B(-1,13,-4,minecraft:spruce_leaves)
B(-1,14,-4,minecraft:spruce_leaves)
B(-1,17,-4,minecraft:spruce_leaves)
B(-1,19,-4,minecraft:spruce_leaves)
B(-1,22,-4,minecraft:spruce_leaves)
B(-1,6,-3,minecraft:spruce_log)
B(-1,7,-3,minecraft:spruce_leaves)
B(-1,8,-3,minecraft:spruce_log)
B(-1,9,-3,minecraft:spruce_leaves)
B(-1,10,-3,minecraft:spruce_leaves)
B(-1,11,-3,minecraft:spruce_leaves)
B(-1,13,-3,minecraft:spruce_leaves)
B(-1,15,-3,minecraft:spruce_leaves)
B(-1,17,-3,minecraft:spruce_leaves)
B(-1,18,-3,minecraft:spruce_leaves)
B(-1,19,-3,minecraft:spruce_log)
B(-1,20,-3,minecraft:spruce_leaves)
B(-1,22,-3,minecraft:spruce_log)
B(-1,23,-3,minecraft:spruce_leaves)
B(-1,24,-3,minecraft:spruce_leaves)
B(-1,10,-2,minecraft:spruce_log)
B(-1,11,-2,minecraft:spruce_leaves)
B(-1,13,-2,minecraft:spruce_leaves)
B(-1,15,-2,minecraft:spruce_log)
B(-1,17,-2,minecraft:spruce_log)
B(-1,18,-2,minecraft:spruce_leaves)
B(-1,20,-2,minecraft:spruce_leaves)
B(-1,22,-2,minecraft:spruce_log)
B(-1,23,-2,minecraft:spruce_leaves)
B(-1,24,-2,minecraft:spruce_log)
B(-1,25,-2,minecraft:spruce_leaves)
B(-1,27,-2,minecraft:spruce_leaves[distance=2,persistent=false])
B(-1,9,-1,minecraft:spruce_leaves)
B(-1,10,-1,minecraft:spruce_log)
B(-1,11,-1,minecraft:spruce_leaves)
B(-1,12,-1,minecraft:spruce_leaves)
B(-1,13,-1,minecraft:spruce_log)
B(-1,14,-1,minecraft:spruce_log)
B(-1,15,-1,minecraft:spruce_log)
B(-1,16,-1,minecraft:spruce_log)
B(-1,17,-1,minecraft:spruce_log)
B(-1,18,-1,minecraft:spruce_log)
B(-1,19,-1,minecraft:spruce_log)
B(-1,20,-1,minecraft:spruce_log)
B(-1,21,-1,minecraft:spruce_log)
B(-1,22,-1,minecraft:spruce_log)
B(-1,23,-1,minecraft:spruce_log)
B(-1,24,-1,minecraft:spruce_log)
B(-1,25,-1,minecraft:spruce_log)
B(-1,26,-1,minecraft:spruce_log)
B(-1,27,-1,minecraft:spruce_leaves)
B(-1,28,-1,minecraft:spruce_leaves)
B(-1,0,0,minecraft:spruce_log)
B(-1,5,0,minecraft:spruce_log)
B(-1,6,0,minecraft:spruce_log)
B(-1,7,0,minecraft:spruce_log)
B(-1,8,0,minecraft:spruce_log)
B(-1,9,0,minecraft:spruce_log)
B(-1,10,0,minecraft:spruce_leaves)
B(-1,11,0,minecraft:spruce_log)
B(-1,12,0,minecraft:spruce_log)
B(-1,13,0,minecraft:spruce_log)
B(-1,14,0,minecraft:spruce_log)
B(-1,15,0,minecraft:spruce_log)
B(-1,16,0,minecraft:spruce_log)
B(-1,17,0,minecraft:spruce_log)
B(-1,18,0,minecraft:spruce_log)
B(-1,20,0,minecraft:spruce_log)
B(-1,21,0,minecraft:spruce_leaves)
B(-1,22,0,minecraft:spruce_log)
B(-1,23,0,minecraft:spruce_leaves)
B(-1,24,0,minecraft:spruce_log)
B(-1,25,0,minecraft:spruce_leaves)
B(-1,26,0,minecraft:spruce_leaves)
B(-1,6,1,minecraft:spruce_log)
B(-1,7,1,minecraft:spruce_leaves)
B(-1,9,1,minecraft:spruce_leaves)
B(-1,12,1,minecraft:spruce_leaves)
B(-1,13,1,minecraft:spruce_log)
B(-1,15,1,minecraft:spruce_leaves)
B(-1,18,1,minecraft:spruce_log)
B(-1,19,1,minecraft:spruce_leaves)
B(-1,20,1,minecraft:spruce_leaves)
B(-1,22,1,minecraft:spruce_leaves)
B(-1,23,1,minecraft:spruce_leaves[distance=2,persistent=false])
B(-1,24,1,minecraft:spruce_leaves)
B(-1,6,2,minecraft:spruce_leaves)
B(-1,12,2,minecraft:spruce_leaves)
B(-1,13,2,minecraft:spruce_log)
B(-1,14,2,minecraft:spruce_leaves)
B(-1,15,2,minecraft:spruce_leaves)
B(-1,18,2,minecraft:spruce_log)
B(-1,19,2,minecraft:spruce_leaves)
B(-1,22,2,minecraft:spruce_leaves[distance=2,persistent=false])
B(-1,5,3,minecraft:spruce_log)
B(-1,6,3,minecraft:spruce_leaves)
B(-1,7,3,minecraft:spruce_log)
B(-1,8,3,minecraft:spruce_leaves)
B(-1,11,3,minecraft:spruce_leaves)
B(-1,13,3,minecraft:spruce_leaves)
B(-1,15,3,minecraft:spruce_leaves)
B(-1,18,3,minecraft:spruce_log)
B(-1,19,3,minecraft:spruce_leaves)
B(-1,5,4,minecraft:spruce_log)
B(-1,6,4,minecraft:spruce_leaves)
B(-1,7,4,minecraft:spruce_leaves)
B(-1,18,4,minecraft:spruce_leaves)
B(-1,5,5,minecraft:spruce_log)
B(-1,6,5,minecraft:spruce_leaves)
B(-1,7,5,minecraft:spruce_leaves)
B(-1,5,6,minecraft:spruce_leaves)
B(0,6,-6,minecraft:spruce_leaves)
B(0,11,-6,minecraft:spruce_leaves)
B(0,6,-5,minecraft:spruce_log)
B(0,7,-5,minecraft:spruce_leaves)
B(0,8,-5,minecraft:spruce_leaves)
B(0,11,-5,minecraft:spruce_log)
B(0,12,-5,minecraft:spruce_leaves)
B(0,13,-5,minecraft:spruce_leaves)
B(0,6,-4,minecraft:spruce_log)
B(0,7,-4,minecraft:spruce_leaves)
B(0,8,-4,minecraft:spruce_leaves)
B(0,11,-4,minecraft:spruce_log)
B(0,12,-4,minecraft:spruce_leaves)
B(0,13,-4,minecraft:spruce_log)
B(0,14,-4,minecraft:spruce_leaves)
B(0,17,-4,minecraft:spruce_leaves)
B(0,21,-4,minecraft:spruce_leaves[distance=2,persistent=false])
B(0,6,-3,minecraft:spruce_log)
B(0,7,-3,minecraft:spruce_leaves)
B(0,8,-3,minecraft:spruce_leaves)
B(0,11,-3,minecraft:spruce_log)
B(0,12,-3,minecraft:spruce_leaves)
B(0,13,-3,minecraft:spruce_log)
B(0,14,-3,minecraft:spruce_leaves)
B(0,15,-3,minecraft:spruce_leaves)
B(0,17,-3,minecraft:spruce_log)
B(0,18,-3,minecraft:spruce_leaves)
B(0,21,-3,minecraft:spruce_leaves)
B(0,22,-3,minecraft:spruce_leaves)
B(0,6,-2,minecraft:spruce_log)
B(0,7,-2,minecraft:spruce_leaves)
B(0,8,-2,minecraft:spruce_log)
B(0,9,-2,minecraft:spruce_leaves)
B(0,10,-2,minecraft:spruce_log)
B(0,11,-2,minecraft:spruce_log)
B(0,12,-2,minecraft:spruce_leaves)
B(0,13,-2,minecraft:spruce_log)
B(0,14,-2,minecraft:spruce_leaves)
B(0,15,-2,minecraft:spruce_leaves)
B(0,17,-2,minecraft:spruce_leaves)
B(0,18,-2,minecraft:spruce_leaves[distance=2,persistent=false])
B(0,19,-2,minecraft:spruce_leaves)
B(0,21,-2,minecraft:spruce_leaves)
B(0,22,-2,minecraft:spruce_leaves)
B(0,23,-2,minecraft:spruce_leaves)
B(0,25,-2,minecraft:spruce_leaves)
B(0,3,-1,minecraft:spruce_log)
B(0,4,-1,minecraft:spruce_log)
B(0,5,-1,minecraft:spruce_log)
B(0,6,-1,minecraft:spruce_log)
B(0,7,-1,minecraft:spruce_log)
B(0,8,-1,minecraft:spruce_log)
B(0,9,-1,minecraft:spruce_log)
B(0,10,-1,minecraft:spruce_log)
B(0,11,-1,minecraft:spruce_log)
B(0,12,-1,minecraft:spruce_log)
B(0,13,-1,minecraft:spruce_log)
B(0,14,-1,minecraft:spruce_log)
B(0,15,-1,minecraft:spruce_log)
B(0,16,-1,minecraft:spruce_leaves)
B(0,17,-1,minecraft:spruce_log)
B(0,18,-1,minecraft:spruce_leaves)
B(0,19,-1,minecraft:spruce_log)
B(0,20,-1,minecraft:spruce_leaves)
B(0,21,-1,minecraft:spruce_log)
B(0,22,-1,minecraft:spruce_leaves)
B(0,23,-1,minecraft:spruce_log)
B(0,24,-1,minecraft:spruce_leaves)
B(0,25,-1,minecraft:spruce_log)
B(0,26,-1,minecraft:spruce_leaves)
B(0,27,-1,minecraft:spruce_leaves[distance=2,persistent=false])
B(0,0,0,minecraft:spruce_log)
B(0,1,0,minecraft:spruce_log)
B(0,2,0,minecraft:spruce_log)
B(0,3,0,minecraft:spruce_log)
B(0,4,0,minecraft:spruce_log)
B(0,5,0,minecraft:spruce_log)
B(0,6,0,minecraft:spruce_log)
B(0,7,0,minecraft:spruce_log)
B(0,8,0,minecraft:spruce_log)
B(0,9,0,minecraft:spruce_log)
B(0,10,0,minecraft:spruce_log)
B(0,11,0,minecraft:spruce_log)
B(0,12,0,minecraft:spruce_log)
B(0,13,0,minecraft:spruce_log)
B(0,14,0,minecraft:spruce_log)
B(0,15,0,minecraft:spruce_log)
B(0,16,0,minecraft:spruce_log)
B(0,17,0,minecraft:spruce_log)
B(0,20,0,minecraft:spruce_log)
B(0,21,0,minecraft:spruce_leaves)
B(0,22,0,minecraft:spruce_leaves)
B(0,23,0,minecraft:spruce_leaves)
B(0,25,0,minecraft:spruce_leaves)
B(0,0,1,minecraft:spruce_log)
B(0,1,1,minecraft:spruce_log)
B(0,2,1,minecraft:spruce_log)
B(0,3,1,minecraft:spruce_log)
B(0,4,1,minecraft:spruce_log)
B(0,5,1,minecraft:spruce_log)
B(0,6,1,minecraft:spruce_log)
B(0,7,1,minecraft:spruce_log)
B(0,8,1,minecraft:spruce_leaves)
B(0,9,1,minecraft:spruce_log)
B(0,10,1,minecraft:spruce_leaves)
B(0,12,1,minecraft:spruce_log)
B(0,13,1,minecraft:spruce_leaves)
B(0,15,1,minecraft:spruce_log)
B(0,16,1,minecraft:spruce_leaves)
B(0,17,1,minecraft:spruce_leaves)
B(0,18,1,minecraft:spruce_log)
B(0,19,1,minecraft:spruce_leaves)
B(0,20,1,minecraft:spruce_log)
B(0,21,1,minecraft:spruce_leaves)
B(0,0,2,minecraft:spruce_log)
B(0,5,2,minecraft:spruce_log)
B(0,6,2,minecraft:spruce_leaves)
B(0,7,2,minecraft:spruce_log)
B(0,8,2,minecraft:spruce_leaves)
B(0,9,2,minecraft:spruce_log)
B(0,10,2,minecraft:spruce_leaves)
B(0,11,2,minecraft:spruce_log)
B(0,12,2,minecraft:spruce_log)
B(0,13,2,minecraft:spruce_leaves)
B(0,15,2,minecraft:spruce_log)
B(0,16,2,minecraft:spruce_leaves)
B(0,18,2,minecraft:spruce_leaves)
B(0,19,2,minecraft:spruce_leaves[distance=2,persistent=false])
B(0,20,2,minecraft:spruce_leaves)
B(0,5,3,minecraft:spruce_log)
B(0,6,3,minecraft:spruce_leaves)
B(0,7,3,minecraft:spruce_log)
B(0,8,3,minecraft:spruce_leaves)
B(0,9,3,minecraft:spruce_leaves)
B(0,11,3,minecraft:spruce_log)
B(0,12,3,minecraft:spruce_leaves)
B(0,13,3,minecraft:spruce_leaves)
B(0,15,3,minecraft:spruce_log)
B(0,16,3,minecraft:spruce_leaves)
B(0,18,3,minecraft:spruce_leaves)
B(0,5,4,minecraft:spruce_leaves)
B(0,7,4,minecraft:spruce_log)
B(0,8,4,minecraft:spruce_leaves)
B(0,11,4,minecraft:spruce_leaves)
B(0,13,4,minecraft:spruce_leaves)
B(0,15,4,minecraft:spruce_leaves)
B(0,5,5,minecraft:spruce_leaves)
B(0,7,5,minecraft:spruce_log)
B(0,8,5,minecraft:spruce_leaves)
B(0,5,6,minecraft:spruce_leaves[distance=2,persistent=false])
B(0,7,6,minecraft:spruce_leaves)
B(1,6,-5,minecraft:spruce_leaves)
B(1,11,-5,minecraft:spruce_leaves)
B(1,6,-4,minecraft:spruce_leaves)
B(1,8,-4,minecraft:spruce_leaves)
B(1,11,-4,minecraft:spruce_leaves)
B(1,13,-4,minecraft:spruce_leaves)
B(1,15,-4,minecraft:spruce_leaves)
B(1,17,-4,minecraft:spruce_leaves)
B(1,21,-4,minecraft:spruce_leaves)
B(1,6,-3,minecraft:spruce_log)
B(1,7,-3,minecraft:spruce_leaves)
B(1,8,-3,minecraft:spruce_log)
B(1,9,-3,minecraft:spruce_leaves)
B(1,11,-3,minecraft:spruce_leaves)
B(1,13,-3,minecraft:spruce_leaves)
B(1,15,-3,minecraft:spruce_log)
B(1,16,-3,minecraft:spruce_leaves)
B(1,17,-3,minecraft:spruce_log)
B(1,18,-3,minecraft:spruce_leaves)
B(1,19,-3,minecraft:spruce_leaves)
B(1,21,-3,minecraft:spruce_log)
B(1,22,-3,minecraft:spruce_leaves)
B(1,6,-2,minecraft:spruce_leaves)
B(1,8,-2,minecraft:spruce_leaves)
B(1,11,-2,minecraft:spruce_log)
B(1,12,-2,minecraft:spruce_leaves)
B(1,15,-2,minecraft:spruce_log)
B(1,16,-2,minecraft:spruce_leaves)
B(1,17,-2,minecraft:spruce_leaves)
B(1,19,-2,minecraft:spruce_log)
B(1,20,-2,minecraft:spruce_leaves)
B(1,21,-2,minecraft:spruce_log)
B(1,22,-2,minecraft:spruce_leaves)
B(1,0,-1,minecraft:spruce_log)
B(1,1,-1,minecraft:spruce_log)
B(1,2,-1,minecraft:spruce_log)
B(1,6,-1,minecraft:spruce_leaves)
B(1,8,-1,minecraft:spruce_log)
B(1,9,-1,minecraft:spruce_log)
B(1,10,-1,minecraft:spruce_leaves)
B(1,11,-1,minecraft:spruce_log)
B(1,12,-1,minecraft:spruce_leaves)
B(1,15,-1,minecraft:spruce_log)
B(1,16,-1,minecraft:spruce_leaves)
B(1,17,-1,minecraft:spruce_log)
B(1,18,-1,minecraft:spruce_leaves)
B(1,19,-1,minecraft:spruce_log)
B(1,20,-1,minecraft:spruce_leaves)
B(1,21,-1,minecraft:spruce_leaves)
B(1,23,-1,minecraft:spruce_leaves)
B(1,24,-1,minecraft:spruce_leaves[distance=2,persistent=false])
B(1,25,-1,minecraft:spruce_leaves)
B(1,0,0,minecraft:spruce_log)
B(1,1,0,minecraft:spruce_log)
B(1,2,0,minecraft:spruce_log)
B(1,3,0,minecraft:spruce_log)
B(1,4,0,minecraft:spruce_log)
B(1,5,0,minecraft:spruce_log)
B(1,6,0,minecraft:spruce_log)
B(1,7,0,minecraft:spruce_log)
B(1,8,0,minecraft:spruce_log)
B(1,9,0,minecraft:spruce_log)
B(1,10,0,minecraft:spruce_log)
B(1,11,0,minecraft:spruce_log)
B(1,12,0,minecraft:spruce_log)
B(1,13,0,minecraft:spruce_log)
B(1,14,0,minecraft:spruce_leaves)
B(1,15,0,minecraft:spruce_leaves)
B(1,17,0,minecraft:spruce_log)
B(1,18,0,minecraft:spruce_leaves)
B(1,19,0,minecraft:spruce_leaves)
B(1,20,0,minecraft:spruce_leaves)
B(1,23,0,minecraft:spruce_log)
B(1,24,0,minecraft:spruce_leaves)
B(1,0,1,minecraft:spruce_log)
B(1,1,1,minecraft:spruce_log)
B(1,2,1,minecraft:spruce_log)
B(1,3,1,minecraft:spruce_log)
B(1,4,1,minecraft:spruce_log)
B(1,5,1,minecraft:spruce_log)
B(1,6,1,minecraft:spruce_log)
B(1,7,1,minecraft:spruce_log)
B(1,8,1,minecraft:spruce_leaves)
B(1,9,1,minecraft:spruce_leaves)
B(1,13,1,minecraft:spruce_leaves)
B(1,15,1,minecraft:spruce_leaves)
B(1,17,1,minecraft:spruce_log)
B(1,18,1,minecraft:spruce_leaves)
B(1,20,1,minecraft:spruce_leaves)
B(1,23,1,minecraft:spruce_leaves)
B(1,0,2,minecraft:spruce_log)
B(1,1,2,minecraft:spruce_log)
B(1,2,2,minecraft:spruce_log)
B(1,7,2,minecraft:spruce_leaves)
B(1,8,2,minecraft:spruce_leaves)
B(1,9,2,minecraft:spruce_log)
B(1,10,2,minecraft:spruce_leaves)
B(1,11,2,minecraft:spruce_leaves)
B(1,12,2,minecraft:spruce_leaves)
B(1,13,2,minecraft:spruce_leaves)
B(1,15,2,minecraft:spruce_log)
B(1,16,2,minecraft:spruce_leaves)
B(1,17,2,minecraft:spruce_leaves)
B(1,18,2,minecraft:spruce_leaves[distance=2,persistent=false])
B(1,20,2,minecraft:spruce_leaves[distance=2,persistent=false])
B(1,5,3,minecraft:spruce_log)
B(1,6,3,minecraft:spruce_leaves)
B(1,7,3,minecraft:spruce_leaves)
B(1,9,3,minecraft:spruce_log)
B(1,10,3,minecraft:spruce_leaves)
B(1,11,3,minecraft:spruce_leaves)
B(1,13,3,minecraft:spruce_log)
B(1,14,3,minecraft:spruce_leaves)
B(1,15,3,minecraft:spruce_leaves)
B(1,16,3,minecraft:spruce_leaves[distance=2,persistent=false])
B(1,5,4,minecraft:spruce_log)
B(1,6,4,minecraft:spruce_leaves)
B(1,7,4,minecraft:spruce_log)
B(1,8,4,minecraft:spruce_leaves)
B(1,9,4,minecraft:spruce_leaves)
B(1,13,4,minecraft:spruce_log)
B(1,14,4,minecraft:spruce_leaves)
B(1,5,5,minecraft:spruce_leaves)
B(1,7,5,minecraft:spruce_leaves)
B(1,13,5,minecraft:spruce_leaves)
B(2,6,-5,minecraft:spruce_leaves)
B(2,6,-4,minecraft:spruce_log)
B(2,7,-4,minecraft:spruce_leaves)
B(2,9,-4,minecraft:spruce_leaves)
B(2,11,-4,minecraft:spruce_leaves)
B(2,6,-3,minecraft:spruce_leaves)
B(2,9,-3,minecraft:spruce_log)
B(2,10,-3,minecraft:spruce_leaves)
B(2,11,-3,minecraft:spruce_log)
B(2,12,-3,minecraft:spruce_leaves)
B(2,15,-3,minecraft:spruce_leaves)
B(2,17,-3,minecraft:spruce_leaves)
B(2,21,-3,minecraft:spruce_leaves)
B(2,5,-2,minecraft:spruce_leaves)
B(2,9,-2,minecraft:spruce_log)
B(2,10,-2,minecraft:spruce_leaves)
B(2,11,-2,minecraft:spruce_leaves)
B(2,13,-2,minecraft:spruce_leaves)
B(2,15,-2,minecraft:spruce_log)
B(2,16,-2,minecraft:spruce_leaves)
B(2,17,-2,minecraft:spruce_leaves[distance=2,persistent=false])
B(2,19,-2,minecraft:spruce_leaves)
B(2,21,-2,minecraft:spruce_leaves)
B(2,7,-1,minecraft:spruce_leaves)
B(2,8,-1,minecraft:spruce_leaves)
B(2,9,-1,minecraft:spruce_log)
B(2,10,-1,minecraft:spruce_leaves)
B(2,11,-1,minecraft:spruce_log)
B(2,12,-1,minecraft:spruce_leaves)
B(2,13,-1,minecraft:spruce_log)
B(2,14,-1,minecraft:spruce_leaves)
B(2,15,-1,minecraft:spruce_leaves)
B(2,17,-1,minecraft:spruce_leaves)
B(2,19,-1,minecraft:spruce_leaves)
B(2,21,-1,minecraft:spruce_leaves[distance=2,persistent=false])
B(2,0,0,minecraft:spruce_log)
B(2,1,0,minecraft:spruce_log)
B(2,5,0,minecraft:spruce_log)
B(2,6,0,minecraft:spruce_leaves)
B(2,7,0,minecraft:spruce_log)
B(2,8,0,minecraft:spruce_leaves)
B(2,9,0,minecraft:spruce_log)
B(2,10,0,minecraft:spruce_leaves)
B(2,11,0,minecraft:spruce_log)
B(2,12,0,minecraft:spruce_leaves)
B(2,13,0,minecraft:spruce_log)
B(2,14,0,minecraft:spruce_leaves)
B(2,17,0,minecraft:spruce_log)
B(2,18,0,minecraft:spruce_leaves)
B(2,23,0,minecraft:spruce_leaves)
B(2,0,1,minecraft:spruce_log)
B(2,1,1,minecraft:spruce_log)
B(2,2,1,minecraft:spruce_log)
B(2,7,1,minecraft:spruce_log)
B(2,8,1,minecraft:spruce_leaves)
B(2,13,1,minecraft:spruce_leaves)
B(2,15,1,minecraft:spruce_leaves)
B(2,17,1,minecraft:spruce_leaves)
B(2,0,2,minecraft:spruce_log)
B(2,7,2,minecraft:spruce_log)
B(2,8,2,minecraft:spruce_leaves)
B(2,9,2,minecraft:spruce_leaves)
B(2,11,2,minecraft:spruce_leaves[distance=2,persistent=false])
B(2,15,2,minecraft:spruce_log)
B(2,16,2,minecraft:spruce_leaves)
B(2,5,3,minecraft:spruce_leaves)
B(2,6,3,minecraft:spruce_leaves[distance=2,persistent=false])
B(2,7,3,minecraft:spruce_leaves)
B(2,9,3,minecraft:spruce_leaves)
B(2,13,3,minecraft:spruce_leaves)
B(2,15,3,minecraft:spruce_leaves)
B(2,5,4,minecraft:spruce_leaves)
B(2,7,4,minecraft:spruce_leaves)
B(2,13,4,minecraft:spruce_leaves)
B(3,6,-4,minecraft:spruce_leaves)
B(3,5,-3,minecraft:spruce_leaves)
B(3,9,-3,minecraft:spruce_leaves)
B(3,11,-3,minecraft:spruce_leaves)
B(3,15,-3,minecraft:spruce_leaves)
B(3,5,-2,minecraft:spruce_log)
B(3,6,-2,minecraft:spruce_leaves)
B(3,9,-2,minecraft:spruce_log)
B(3,10,-2,minecraft:spruce_leaves)
B(3,13,-2,minecraft:spruce_leaves)
B(3,15,-2,minecraft:spruce_log)
B(3,16,-2,minecraft:spruce_leaves)
B(3,5,-1,minecraft:spruce_log)
B(3,6,-1,minecraft:spruce_leaves)
B(3,7,-1,minecraft:spruce_leaves)
B(3,9,-1,minecraft:spruce_leaves)
B(3,10,-1,minecraft:spruce_leaves[distance=2,persistent=false])
B(3,11,-1,minecraft:spruce_leaves)
B(3,12,-1,minecraft:spruce_leaves)
B(3,13,-1,minecraft:spruce_log)
B(3,14,-1,minecraft:spruce_leaves)
B(3,15,-1,minecraft:spruce_leaves)
B(3,17,-1,minecraft:spruce_leaves)
B(3,5,0,minecraft:spruce_log)
B(3,6,0,minecraft:spruce_leaves)
B(3,7,0,minecraft:spruce_log)
B(3,8,0,minecraft:spruce_leaves)
B(3,9,0,minecraft:spruce_log)
B(3,10,0,minecraft:spruce_leaves)
B(3,11,0,minecraft:spruce_leaves)
B(3,12,0,minecraft:spruce_log)
B(3,13,0,minecraft:spruce_leaves)
B(3,14,0,minecraft:spruce_leaves[distance=2,persistent=false])
B(3,17,0,minecraft:spruce_log)
B(3,18,0,minecraft:spruce_leaves)
B(3,5,1,minecraft:spruce_log)
B(3,6,1,minecraft:spruce_leaves)
B(3,7,1,minecraft:spruce_leaves)
B(3,9,1,minecraft:spruce_log)
B(3,10,1,minecraft:spruce_leaves)
B(3,12,1,minecraft:spruce_log)
B(3,13,1,minecraft:spruce_leaves)
B(3,17,1,minecraft:spruce_leaves)
B(3,5,2,minecraft:spruce_leaves)
B(3,7,2,minecraft:spruce_log)
B(3,8,2,minecraft:spruce_leaves)
B(3,9,2,minecraft:spruce_leaves)
B(3,12,2,minecraft:spruce_leaves)
B(3,15,2,minecraft:spruce_leaves)
B(3,7,3,minecraft:spruce_log)
B(3,8,3,minecraft:spruce_leaves)
B(3,7,4,minecraft:spruce_leaves)
B(4,9,-3,minecraft:spruce_leaves)
B(4,5,-2,minecraft:spruce_leaves)
B(4,9,-2,minecraft:spruce_log)
B(4,10,-2,minecraft:spruce_leaves)
B(4,15,-2,minecraft:spruce_leaves)
B(4,5,-1,minecraft:spruce_log)
B(4,6,-1,minecraft:spruce_leaves)
B(4,9,-1,minecraft:spruce_leaves)
B(4,12,-1,minecraft:spruce_leaves)
B(4,13,-1,minecraft:spruce_leaves)
B(4,5,0,minecraft:spruce_leaves)
B(4,7,0,minecraft:spruce_leaves)
B(4,9,0,minecraft:spruce_log)
B(4,10,0,minecraft:spruce_leaves)
B(4,12,0,minecraft:spruce_log)
B(4,13,0,minecraft:spruce_leaves)
B(4,17,0,minecraft:spruce_leaves)
B(4,5,1,minecraft:spruce_log)
B(4,6,1,minecraft:spruce_leaves)
B(4,9,1,minecraft:spruce_leaves)
B(4,12,1,minecraft:spruce_leaves)
B(4,5,2,minecraft:spruce_leaves)
B(4,7,2,minecraft:spruce_leaves)
B(4,7,3,minecraft:spruce_leaves)
B(5,5,-2,minecraft:spruce_leaves)
B(5,9,-2,minecraft:spruce_leaves)
B(5,5,-1,minecraft:spruce_log)
B(5,6,-1,minecraft:spruce_leaves)
B(5,9,-1,minecraft:spruce_leaves[distance=2,persistent=false])
B(5,5,0,minecraft:spruce_leaves)
B(5,9,0,minecraft:spruce_leaves)
B(5,12,0,minecraft:spruce_leaves)
B(5,5,1,minecraft:spruce_leaves)
B(6,5,-1,minecraft:spruce_leaves)

#######################################################################
# +-----------------------------------------------------------------+ #
# |                            BO3 checks                           | #
# +-----------------------------------------------------------------+ #
#######################################################################


#######################################################################
# +-----------------------------------------------------------------+ #
# |                             Branches                            | #
# +-----------------------------------------------------------------+ #
#######################################################################


#######################################################################
# +-----------------------------------------------------------------+ #
# |                             Entities                            | #
# +-----------------------------------------------------------------+ #
#######################################################################

